<sdf version='1.6'>
  <world name='default'>
    <light name='sun' type='directional'>
      <cast_shadows>1</cast_shadows>
      <pose frame=''>0 0 10 0 -0 0</pose>
      <diffuse>0.8 0.8 0.8 1</diffuse>
      <specular>0.2 0.2 0.2 1</specular>
      <attenuation>
        <range>1000</range>
        <constant>0.9</constant>
        <linear>0.01</linear>
        <quadratic>0.001</quadratic>
      </attenuation>
      <direction>-0.5 0.1 -0.9</direction>
    </light>
    <model name='ground_plane'>
      <static>1</static>
      <link name='link'>
        <collision name='collision'>
          <geometry>
            <plane>
              <normal>0 0 1</normal>
              <size>100 100</size>
            </plane>
          </geometry>
          <surface>
            <friction>
              <ode>
                <mu>100</mu>
                <mu2>50</mu2>
              </ode>
              <torsional>
                <ode/>
              </torsional>
            </friction>
            <contact>
              <ode/>
            </contact>
            <bounce/>
          </surface>
          <max_contacts>10</max_contacts>
        </collision>
        <visual name='visual'>
          <cast_shadows>0</cast_shadows>
          <geometry>
            <plane>
              <normal>0 0 1</normal>
              <size>100 100</size>
            </plane>
          </geometry>
          <material>
            <script>
              <uri>file://media/materials/scripts/gazebo.material</uri>
              <name>Gazebo/Grey</name>
            </script>
          </material>
        </visual>
        <self_collide>0</self_collide>
        <kinematic>0</kinematic>
      </link>
    </model>
    <gravity>0 0 -9.8</gravity>
    <magnetic_field>6e-06 2.3e-05 -4.2e-05</magnetic_field>
    <atmosphere type='adiabatic'/>
    <physics name='default_physics' default='0' type='ode'>
      <max_step_size>0.001</max_step_size>
      <real_time_factor>1</real_time_factor>
      <real_time_update_rate>1000</real_time_update_rate>
    </physics>
    <scene>
      <ambient>0.4 0.4 0.4 1</ambient>
      <background>0.7 0.7 0.7 1</background>
      <shadows>1</shadows>
    </scene>
    <spherical_coordinates>
      <surface_model>EARTH_WGS84</surface_model>
      <latitude_deg>0</latitude_deg>
      <longitude_deg>0</longitude_deg>
      <elevation>0</elevation>
      <heading_deg>0</heading_deg>
    </spherical_coordinates>
    <model name='vrc_driving_terrain'>
      <static>1</static>
      <link name='link'>
        <collision name='collision'>
          <geometry>
            <heightmap>
              <uri>model://vrc_driving_terrain/materials/textures/heightmap.png</uri>
              <size>500 500 118</size>
              <pos>0 0 -15</pos>
              <texture>
                <size>10</size>
                <diffuse>__default__</diffuse>
                <normal>__default__</normal>
              </texture>
              <blend>
                <min_height>0</min_height>
                <fade_dist>0</fade_dist>
              </blend>
            </heightmap>
          </geometry>
          <max_contacts>10</max_contacts>
          <surface>
            <contact>
              <ode/>
            </contact>
            <bounce/>
            <friction>
              <torsional>
                <ode/>
              </torsional>
              <ode/>
            </friction>
          </surface>
        </collision>
        <visual name='visual'>
          <geometry>
            <heightmap>
              <texture>
                <diffuse>file://media/materials/textures/dirt_diffusespecular.png</diffuse>
                <normal>file://media/materials/textures/flat_normal.png</normal>
                <size>5</size>
              </texture>
              <texture>
                <diffuse>file://media/materials/textures/grass_diffusespecular.png</diffuse>
                <normal>file://media/materials/textures/flat_normal.png</normal>
                <size>5</size>
              </texture>
              <texture>
                <diffuse>file://media/materials/textures/fungus_diffusespecular.png</diffuse>
                <normal>file://media/materials/textures/flat_normal.png</normal>
                <size>20</size>
              </texture>
              <blend>
                <min_height>15</min_height>
                <fade_dist>5</fade_dist>
              </blend>
              <blend>
                <min_height>30</min_height>
                <fade_dist>10</fade_dist>
              </blend>
              <uri>model://vrc_driving_terrain/materials/textures/heightmap.png</uri>
              <size>500 500 118</size>
              <pos>0 0 -15</pos>
            </heightmap>
          </geometry>
        </visual>
        <self_collide>0</self_collide>
        <kinematic>0</kinematic>
      </link>
      <link name='grass_plane'>
        <collision name='collision'>
          <geometry>
            <plane>
              <normal>0 0 1</normal>
              <size>500 500</size>
            </plane>
          </geometry>
          <surface>
            <friction>
              <ode>
                <mu>0.5</mu>
                <mu2>0.5</mu2>
              </ode>
              <torsional>
                <ode/>
              </torsional>
            </friction>
            <contact>
              <ode/>
            </contact>
            <bounce/>
          </surface>
          <max_contacts>10</max_contacts>
        </collision>
        <visual name='visual_0'>
          <pose frame=''>0 0 0 0 -0 0</pose>
          <cast_shadows>0</cast_shadows>
          <geometry>
            <plane>
              <normal>0 0 1</normal>
              <size>500 500</size>
            </plane>
          </geometry>
          <material>
            <script>
              <uri>model://vrc_driving_terrain/materials/scripts</uri>
              <uri>model://vrc_driving_terrain/materials/textures</uri>
              <name>vrc/grass</name>
            </script>
          </material>
        </visual>
        <self_collide>0</self_collide>
        <kinematic>0</kinematic>
      </link>
      <pose frame=''>-1.87065 -3.0804 0 0 -0 0</pose>
    </model>
    <model name='oak_tree_clone'>
      <static>1</static>
      <link name='link'>
        <collision name='collision'>
          <geometry>
            <mesh>
              <uri>model://oak_tree/meshes/oak_tree.dae</uri>
            </mesh>
          </geometry>
          <max_contacts>10</max_contacts>
          <surface>
            <contact>
              <ode/>
            </contact>
            <bounce/>
            <friction>
              <torsional>
                <ode/>
              </torsional>
              <ode/>
            </friction>
          </surface>
        </collision>
        <visual name='branch'>
          <geometry>
            <mesh>
              <uri>model://oak_tree/meshes/oak_tree.dae</uri>
              <submesh>
                <name>Branch</name>
              </submesh>
            </mesh>
          </geometry>
          <material>
            <script>
              <uri>model://oak_tree/materials/scripts/</uri>
              <uri>model://oak_tree/materials/textures/</uri>
              <name>OakTree/Branch</name>
            </script>
          </material>
        </visual>
        <visual name='bark'>
          <geometry>
            <mesh>
              <uri>model://oak_tree/meshes/oak_tree.dae</uri>
              <submesh>
                <name>Bark</name>
              </submesh>
            </mesh>
          </geometry>
          <material>
            <script>
              <uri>model://oak_tree/materials/scripts/</uri>
              <uri>model://oak_tree/materials/textures/</uri>
              <name>OakTree/Bark</name>
            </script>
          </material>
        </visual>
        <self_collide>0</self_collide>
        <kinematic>0</kinematic>
      </link>
      <pose frame=''>31.2842 5.74333 0 0 -0 0</pose>
    </model>
    <model name='oak_tree_clone_0'>
      <static>1</static>
      <link name='link'>
        <collision name='collision'>
          <geometry>
            <mesh>
              <uri>model://oak_tree/meshes/oak_tree.dae</uri>
            </mesh>
          </geometry>
          <max_contacts>10</max_contacts>
          <surface>
            <contact>
              <ode/>
            </contact>
            <bounce/>
            <friction>
              <torsional>
                <ode/>
              </torsional>
              <ode/>
            </friction>
          </surface>
        </collision>
        <visual name='branch'>
          <geometry>
            <mesh>
              <uri>model://oak_tree/meshes/oak_tree.dae</uri>
              <submesh>
                <name>Branch</name>
              </submesh>
            </mesh>
          </geometry>
          <material>
            <script>
              <uri>model://oak_tree/materials/scripts/</uri>
              <uri>model://oak_tree/materials/textures/</uri>
              <name>OakTree/Branch</name>
            </script>
          </material>
        </visual>
        <visual name='bark'>
          <geometry>
            <mesh>
              <uri>model://oak_tree/meshes/oak_tree.dae</uri>
              <submesh>
                <name>Bark</name>
              </submesh>
            </mesh>
          </geometry>
          <material>
            <script>
              <uri>model://oak_tree/materials/scripts/</uri>
              <uri>model://oak_tree/materials/textures/</uri>
              <name>OakTree/Bark</name>
            </script>
          </material>
        </visual>
        <self_collide>0</self_collide>
        <kinematic>0</kinematic>
      </link>
      <pose frame=''>-8 17.5691 0 0 -0 0</pose>
    </model>
    <model name='oak_tree_clone_1'>
      <static>1</static>
      <link name='link'>
        <collision name='collision'>
          <geometry>
            <mesh>
              <uri>model://oak_tree/meshes/oak_tree.dae</uri>
            </mesh>
          </geometry>
          <max_contacts>10</max_contacts>
          <surface>
            <contact>
              <ode/>
            </contact>
            <bounce/>
            <friction>
              <torsional>
                <ode/>
              </torsional>
              <ode/>
            </friction>
          </surface>
        </collision>
        <visual name='branch'>
          <geometry>
            <mesh>
              <uri>model://oak_tree/meshes/oak_tree.dae</uri>
              <submesh>
                <name>Branch</name>
              </submesh>
            </mesh>
          </geometry>
          <material>
            <script>
              <uri>model://oak_tree/materials/scripts/</uri>
              <uri>model://oak_tree/materials/textures/</uri>
              <name>OakTree/Branch</name>
            </script>
          </material>
        </visual>
        <visual name='bark'>
          <geometry>
            <mesh>
              <uri>model://oak_tree/meshes/oak_tree.dae</uri>
              <submesh>
                <name>Bark</name>
              </submesh>
            </mesh>
          </geometry>
          <material>
            <script>
              <uri>model://oak_tree/materials/scripts/</uri>
              <uri>model://oak_tree/materials/textures/</uri>
              <name>OakTree/Bark</name>
            </script>
          </material>
        </visual>
        <self_collide>0</self_collide>
        <kinematic>0</kinematic>
      </link>
      <pose frame=''>19.0726 14.9062 0 0 -0 0</pose>
    </model>
    <model name='oak_tree_clone_2'>
      <static>1</static>
      <link name='link'>
        <collision name='collision'>
          <geometry>
            <mesh>
              <uri>model://oak_tree/meshes/oak_tree.dae</uri>
            </mesh>
          </geometry>
          <max_contacts>10</max_contacts>
          <surface>
            <contact>
              <ode/>
            </contact>
            <bounce/>
            <friction>
              <torsional>
                <ode/>
              </torsional>
              <ode/>
            </friction>
          </surface>
        </collision>
        <visual name='branch'>
          <geometry>
            <mesh>
              <uri>model://oak_tree/meshes/oak_tree.dae</uri>
              <submesh>
                <name>Branch</name>
              </submesh>
            </mesh>
          </geometry>
          <material>
            <script>
              <uri>model://oak_tree/materials/scripts/</uri>
              <uri>model://oak_tree/materials/textures/</uri>
              <name>OakTree/Branch</name>
            </script>
          </material>
        </visual>
        <visual name='bark'>
          <geometry>
            <mesh>
              <uri>model://oak_tree/meshes/oak_tree.dae</uri>
              <submesh>
                <name>Bark</name>
              </submesh>
            </mesh>
          </geometry>
          <material>
            <script>
              <uri>model://oak_tree/materials/scripts/</uri>
              <uri>model://oak_tree/materials/textures/</uri>
              <name>OakTree/Bark</name>
            </script>
          </material>
        </visual>
        <self_collide>0</self_collide>
        <kinematic>0</kinematic>
      </link>
      <pose frame=''>-22.3034 0.187197 0 0 -0 0</pose>
    </model>
    <model name='oak_tree_clone_3'>
      <static>1</static>
      <link name='link'>
        <collision name='collision'>
          <geometry>
            <mesh>
              <uri>model://oak_tree/meshes/oak_tree.dae</uri>
            </mesh>
          </geometry>
          <max_contacts>10</max_contacts>
          <surface>
            <contact>
              <ode/>
            </contact>
            <bounce/>
            <friction>
              <torsional>
                <ode/>
              </torsional>
              <ode/>
            </friction>
          </surface>
        </collision>
        <visual name='branch'>
          <geometry>
            <mesh>
              <uri>model://oak_tree/meshes/oak_tree.dae</uri>
              <submesh>
                <name>Branch</name>
              </submesh>
            </mesh>
          </geometry>
          <material>
            <script>
              <uri>model://oak_tree/materials/scripts/</uri>
              <uri>model://oak_tree/materials/textures/</uri>
              <name>OakTree/Branch</name>
            </script>
          </material>
        </visual>
        <visual name='bark'>
          <geometry>
            <mesh>
              <uri>model://oak_tree/meshes/oak_tree.dae</uri>
              <submesh>
                <name>Bark</name>
              </submesh>
            </mesh>
          </geometry>
          <material>
            <script>
              <uri>model://oak_tree/materials/scripts/</uri>
              <uri>model://oak_tree/materials/textures/</uri>
              <name>OakTree/Bark</name>
            </script>
          </material>
        </visual>
        <self_collide>0</self_collide>
        <kinematic>0</kinematic>
      </link>
      <pose frame=''>17.329 -7.63255 0 0 -0 0</pose>
    </model>
    <model name='oak_tree_clone_4'>
      <static>1</static>
      <link name='link'>
        <collision name='collision'>
          <geometry>
            <mesh>
              <uri>model://oak_tree/meshes/oak_tree.dae</uri>
            </mesh>
          </geometry>
          <max_contacts>10</max_contacts>
          <surface>
            <contact>
              <ode/>
            </contact>
            <bounce/>
            <friction>
              <torsional>
                <ode/>
              </torsional>
              <ode/>
            </friction>
          </surface>
        </collision>
        <visual name='branch'>
          <geometry>
            <mesh>
              <uri>model://oak_tree/meshes/oak_tree.dae</uri>
              <submesh>
                <name>Branch</name>
              </submesh>
            </mesh>
          </geometry>
          <material>
            <script>
              <uri>model://oak_tree/materials/scripts/</uri>
              <uri>model://oak_tree/materials/textures/</uri>
              <name>OakTree/Branch</name>
            </script>
          </material>
        </visual>
        <visual name='bark'>
          <geometry>
            <mesh>
              <uri>model://oak_tree/meshes/oak_tree.dae</uri>
              <submesh>
                <name>Bark</name>
              </submesh>
            </mesh>
          </geometry>
          <material>
            <script>
              <uri>model://oak_tree/materials/scripts/</uri>
              <uri>model://oak_tree/materials/textures/</uri>
              <name>OakTree/Bark</name>
            </script>
          </material>
        </visual>
        <self_collide>0</self_collide>
        <kinematic>0</kinematic>
      </link>
      <pose frame=''>28.2562 -12.871 0 0 -0 0</pose>
    </model>
    <model name='tower_crane'>
      <static>1</static>
      <link name='link'>
        <collision name='collision'>
          <geometry>
            <mesh>
              <uri>model://tower_crane/meshes/tower_crane.dae</uri>
            </mesh>
          </geometry>
          <max_contacts>10</max_contacts>
          <surface>
            <contact>
              <ode/>
            </contact>
            <bounce/>
            <friction>
              <torsional>
                <ode/>
              </torsional>
              <ode/>
            </friction>
          </surface>
        </collision>
        <visual name='visual'>
          <geometry>
            <mesh>
              <uri>model://tower_crane/meshes/tower_crane.dae</uri>
            </mesh>
          </geometry>
        </visual>
        <self_collide>0</self_collide>
        <kinematic>0</kinematic>
      </link>
      <pose frame=''>-39.4575 -32.1664 0 0 -0 0</pose>
    </model>
    <model name='pine_tree'>
      <static>1</static>
      <link name='link'>
        <collision name='collision'>
          <geometry>
            <mesh>
              <uri>model://pine_tree/meshes/pine_tree.dae</uri>
            </mesh>
          </geometry>
          <max_contacts>10</max_contacts>
          <surface>
            <contact>
              <ode/>
            </contact>
            <bounce/>
            <friction>
              <torsional>
                <ode/>
              </torsional>
              <ode/>
            </friction>
          </surface>
        </collision>
        <visual name='branch'>
          <geometry>
            <mesh>
              <uri>model://pine_tree/meshes/pine_tree.dae</uri>
              <submesh>
                <name>Branch</name>
              </submesh>
            </mesh>
          </geometry>
          <material>
            <script>
              <uri>model://pine_tree/materials/scripts/</uri>
              <uri>model://pine_tree/materials/textures/</uri>
              <name>PineTree/Branch</name>
            </script>
          </material>
        </visual>
        <visual name='bark'>
          <geometry>
            <mesh>
              <uri>model://pine_tree/meshes/pine_tree.dae</uri>
              <submesh>
                <name>Bark</name>
              </submesh>
            </mesh>
          </geometry>
          <material>
            <script>
              <uri>model://pine_tree/materials/scripts/</uri>
              <uri>model://pine_tree/materials/textures/</uri>
              <name>PineTree/Bark</name>
            </script>
          </material>
        </visual>
        <self_collide>0</self_collide>
        <kinematic>0</kinematic>
      </link>
      <pose frame=''>-1.14655 -32.7072 0 0 -0 0</pose>
    </model>
    <model name='pine_tree_0'>
      <static>1</static>
      <link name='link'>
        <collision name='collision'>
          <geometry>
            <mesh>
              <uri>model://pine_tree/meshes/pine_tree.dae</uri>
            </mesh>
          </geometry>
          <max_contacts>10</max_contacts>
          <surface>
            <contact>
              <ode/>
            </contact>
            <bounce/>
            <friction>
              <torsional>
                <ode/>
              </torsional>
              <ode/>
            </friction>
          </surface>
        </collision>
        <visual name='branch'>
          <geometry>
            <mesh>
              <uri>model://pine_tree/meshes/pine_tree.dae</uri>
              <submesh>
                <name>Branch</name>
              </submesh>
            </mesh>
          </geometry>
          <material>
            <script>
              <uri>model://pine_tree/materials/scripts/</uri>
              <uri>model://pine_tree/materials/textures/</uri>
              <name>PineTree/Branch</name>
            </script>
          </material>
        </visual>
        <visual name='bark'>
          <geometry>
            <mesh>
              <uri>model://pine_tree/meshes/pine_tree.dae</uri>
              <submesh>
                <name>Bark</name>
              </submesh>
            </mesh>
          </geometry>
          <material>
            <script>
              <uri>model://pine_tree/materials/scripts/</uri>
              <uri>model://pine_tree/materials/textures/</uri>
              <name>PineTree/Bark</name>
            </script>
          </material>
        </visual>
        <self_collide>0</self_collide>
        <kinematic>0</kinematic>
      </link>
      <pose frame=''>-21.297 -19.5762 0 0 -0 0</pose>
    </model>
    <model name='pine_tree_1'>
      <static>1</static>
      <link name='link'>
        <collision name='collision'>
          <geometry>
            <mesh>
              <uri>model://pine_tree/meshes/pine_tree.dae</uri>
            </mesh>
          </geometry>
          <max_contacts>10</max_contacts>
          <surface>
            <contact>
              <ode/>
            </contact>
            <bounce/>
            <friction>
              <torsional>
                <ode/>
              </torsional>
              <ode/>
            </friction>
          </surface>
        </collision>
        <visual name='branch'>
          <geometry>
            <mesh>
              <uri>model://pine_tree/meshes/pine_tree.dae</uri>
              <submesh>
                <name>Branch</name>
              </submesh>
            </mesh>
          </geometry>
          <material>
            <script>
              <uri>model://pine_tree/materials/scripts/</uri>
              <uri>model://pine_tree/materials/textures/</uri>
              <name>PineTree/Branch</name>
            </script>
          </material>
        </visual>
        <visual name='bark'>
          <geometry>
            <mesh>
              <uri>model://pine_tree/meshes/pine_tree.dae</uri>
              <submesh>
                <name>Bark</name>
              </submesh>
            </mesh>
          </geometry>
          <material>
            <script>
              <uri>model://pine_tree/materials/scripts/</uri>
              <uri>model://pine_tree/materials/textures/</uri>
              <name>PineTree/Bark</name>
            </script>
          </material>
        </visual>
        <self_collide>0</self_collide>
        <kinematic>0</kinematic>
      </link>
      <pose frame=''>2.23327 -4.24022 0 0 -0 0</pose>
    </model>
    <model name='suv'>
      <static>1</static>
      <link name='link'>
        <collision name='collision'>
          <pose frame=''>0 0 0 0 0 -1.5708</pose>
          <geometry>
            <mesh>
              <scale>0.06 0.06 0.06</scale>
              <uri>model://suv/meshes/suv.obj</uri>
            </mesh>
          </geometry>
          <max_contacts>10</max_contacts>
          <surface>
            <contact>
              <ode/>
            </contact>
            <bounce/>
            <friction>
              <torsional>
                <ode/>
              </torsional>
              <ode/>
            </friction>
          </surface>
        </collision>
        <visual name='visual'>
          <pose frame=''>0 0 0 0 0 -1.5708</pose>
          <geometry>
            <mesh>
              <scale>0.06 0.06 0.06</scale>
              <uri>model://suv/meshes/suv.obj</uri>
            </mesh>
          </geometry>
        </visual>
        <self_collide>0</self_collide>
        <kinematic>0</kinematic>
      </link>
      <pose frame=''>-11.5275 -23.3683 0 0 -0 0</pose>
    </model>
    <model name='suv_0'>
      <static>1</static>
      <link name='link'>
        <collision name='collision'>
          <pose frame=''>0 0 0 0 0 -1.5708</pose>
          <geometry>
            <mesh>
              <scale>0.06 0.06 0.06</scale>
              <uri>model://suv/meshes/suv.obj</uri>
            </mesh>
          </geometry>
          <max_contacts>10</max_contacts>
          <surface>
            <contact>
              <ode/>
            </contact>
            <bounce/>
            <friction>
              <torsional>
                <ode/>
              </torsional>
              <ode/>
            </friction>
          </surface>
        </collision>
        <visual name='visual'>
          <pose frame=''>0 0 0 0 0 -1.5708</pose>
          <geometry>
            <mesh>
              <scale>0.06 0.06 0.06</scale>
              <uri>model://suv/meshes/suv.obj</uri>
            </mesh>
          </geometry>
        </visual>
        <self_collide>0</self_collide>
        <kinematic>0</kinematic>
      </link>
      <pose frame=''>-7.92143 10.0831 0 0 -0 0</pose>
    </model>
    <model name='bus'>
      <static>1</static>
      <link name='link'>
        <collision name='collision'>
          <geometry>
            <mesh>
              <scale>0.01 0.01 0.01</scale>
              <uri>model://bus/meshes/bus.obj</uri>
            </mesh>
          </geometry>
          <max_contacts>10</max_contacts>
          <surface>
            <contact>
              <ode/>
            </contact>
            <bounce/>
            <friction>
              <torsional>
                <ode/>
              </torsional>
              <ode/>
            </friction>
          </surface>
        </collision>
        <visual name='visual'>
          <geometry>
            <mesh>
              <scale>0.01 0.01 0.01</scale>
              <uri>model://bus/meshes/bus.obj</uri>
            </mesh>
          </geometry>
        </visual>
        <self_collide>0</self_collide>
        <kinematic>0</kinematic>
      </link>
      <pose frame=''>22.0685 -30.3747 0 0 -0 0</pose>
    </model>
    <model name='fire_truck'>
      <static>1</static>
      <link name='link'>
        <collision name='collision'>
          <geometry>
            <mesh>
              <scale>0.1 0.1 0.1</scale>
              <uri>model://fire_truck/meshes/fire_truck.obj</uri>
            </mesh>
          </geometry>
          <max_contacts>10</max_contacts>
          <surface>
            <contact>
              <ode/>
            </contact>
            <bounce/>
            <friction>
              <torsional>
                <ode/>
              </torsional>
              <ode/>
            </friction>
          </surface>
        </collision>
        <visual name='visual'>
          <geometry>
            <mesh>
              <scale>0.1 0.1 0.1</scale>
              <uri>model://fire_truck/meshes/fire_truck.obj</uri>
            </mesh>
          </geometry>
        </visual>
        <self_collide>0</self_collide>
        <kinematic>0</kinematic>
      </link>
      <pose frame=''>48.4895 0.921966 0 0 -0 0</pose>
    </model>
    <model name='prius_hybrid'>
      <pose frame=''>10.4607 1.93314 0.03 0 -0 0</pose>
      <link name='chassis'>
        <inertial>
          <mass>1326</mass>
          <pose frame=''>0 -0.266 0.48 0 -0 0</pose>
          <inertia>
            <ixx>2581.13</ixx>
            <ixy>0</ixy>
            <iyy>591.308</iyy>
            <ixz>0</ixz>
            <iyz>0</iyz>
            <izz>2681.95</izz>
          </inertia>
        </inertial>
        <visual name='chassis_visual'>
          <geometry>
            <mesh>
              <uri>model://prius_hybrid/meshes/Hybrid.obj</uri>
              <scale>0.01 0.01 0.01</scale>
              <submesh>
                <name>Hybrid</name>
                <center>0</center>
              </submesh>
            </mesh>
          </geometry>
        </visual>
        <visual name='interior_visual'>
          <geometry>
            <mesh>
              <uri>model://prius_hybrid/meshes/Hybrid.obj</uri>
              <scale>0.01 0.01 0.01</scale>
              <submesh>
                <name>Hybrid_Interior</name>
                <center>0</center>
              </submesh>
            </mesh>
          </geometry>
        </visual>
        <visual name='windows_visual'>
          <geometry>
            <mesh>
              <uri>model://prius_hybrid/meshes/Hybrid.obj</uri>
              <scale>0.01 0.01 0.01</scale>
              <submesh>
                <name>Hybrid_Windows</name>
                <center>0</center>
              </submesh>
            </mesh>
          </geometry>
        </visual>
        <collision name='chassis'>
          <pose frame=''>0 0.05 0.625 0 -0 0</pose>
          <geometry>
            <box>
              <size>1.7526 2.1 0.95</size>
            </box>
          </geometry>
          <max_contacts>10</max_contacts>
          <surface>
            <contact>
              <ode/>
            </contact>
            <bounce/>
            <friction>
              <torsional>
                <ode/>
              </torsional>
              <ode/>
            </friction>
          </surface>
        </collision>
        <collision name='front_bumper'>
          <pose frame=''>0 -2 0.458488 0 -0 0</pose>
          <geometry>
            <box>
              <size>1.33728 0.48 0.566691</size>
            </box>
          </geometry>
          <max_contacts>10</max_contacts>
          <surface>
            <contact>
              <ode/>
            </contact>
            <bounce/>
            <friction>
              <torsional>
                <ode/>
              </torsional>
              <ode/>
            </friction>
          </surface>
        </collision>
        <collision name='hood'>
          <pose frame=''>0 -1.90084 0.676305 0.341247 -0 0</pose>
          <geometry>
            <box>
              <size>1.59797 0.493107 0.265468</size>
            </box>
          </geometry>
          <max_contacts>10</max_contacts>
          <surface>
            <contact>
              <ode/>
            </contact>
            <bounce/>
            <friction>
              <torsional>
                <ode/>
              </torsional>
              <ode/>
            </friction>
          </surface>
        </collision>
        <collision name='windshield'>
          <pose frame=''>0 -0.875105 1.03227 0.335476 -0 0</pose>
          <geometry>
            <box>
              <size>1.16838 1.65425 0.272347</size>
            </box>
          </geometry>
          <max_contacts>10</max_contacts>
          <surface>
            <contact>
              <ode/>
            </contact>
            <bounce/>
            <friction>
              <torsional>
                <ode/>
              </torsional>
              <ode/>
            </friction>
          </surface>
        </collision>
        <collision name='top_front'>
          <pose frame=''>0 0.161236 1.38604 0.13503 -0 0</pose>
          <geometry>
            <box>
              <size>1.27915 0.625988 0.171868</size>
            </box>
          </geometry>
          <max_contacts>10</max_contacts>
          <surface>
            <contact>
              <ode/>
            </contact>
            <bounce/>
            <friction>
              <torsional>
                <ode/>
              </torsional>
              <ode/>
            </friction>
          </surface>
        </collision>
        <collision name='top_rear'>
          <pose frame=''>0 0.817696 1.36007 -0.068997 0 0</pose>
          <geometry>
            <box>
              <size>1.28513 0.771189 0.226557</size>
            </box>
          </geometry>
          <max_contacts>10</max_contacts>
          <surface>
            <contact>
              <ode/>
            </contact>
            <bounce/>
            <friction>
              <torsional>
                <ode/>
              </torsional>
              <ode/>
            </friction>
          </surface>
        </collision>
        <collision name='rear_window'>
          <pose frame=''>0 1.64053 1.17513 -0.262017 0 0</pose>
          <geometry>
            <box>
              <size>1.26785 1.11634 0.244286</size>
            </box>
          </geometry>
          <max_contacts>10</max_contacts>
          <surface>
            <contact>
              <ode/>
            </contact>
            <bounce/>
            <friction>
              <torsional>
                <ode/>
              </torsional>
              <ode/>
            </friction>
          </surface>
        </collision>
        <collision name='trunk'>
          <pose frame=''>0 1.63706 0.88818 0 -0 0</pose>
          <geometry>
            <box>
              <size>1.78806 1.13899 0.482746</size>
            </box>
          </geometry>
          <max_contacts>10</max_contacts>
          <surface>
            <contact>
              <ode/>
            </contact>
            <bounce/>
            <friction>
              <torsional>
                <ode/>
              </torsional>
              <ode/>
            </friction>
          </surface>
        </collision>
        <collision name='back_bumper'>
          <pose frame=''>0 2.05445 0.57787 0 -0 0</pose>
          <geometry>
            <box>
              <size>1.78165 0.512093 0.581427</size>
            </box>
          </geometry>
          <max_contacts>10</max_contacts>
          <surface>
            <contact>
              <ode/>
            </contact>
            <bounce/>
            <friction>
              <torsional>
                <ode/>
              </torsional>
              <ode/>
            </friction>
          </surface>
        </collision>
        <self_collide>0</self_collide>
        <kinematic>0</kinematic>
      </link>
      <link name='steering_wheel'>
        <pose frame=''>0.357734 -0.627868 0.988243 -1.3021 0 0</pose>
        <inertial>
          <mass>1</mass>
          <inertia>
            <ixx>0.145833</ixx>
            <ixy>0</ixy>
            <ixz>0</ixz>
            <iyy>0.145833</iyy>
            <iyz>0</iyz>
            <izz>0.125</izz>
          </inertia>
        </inertial>
        <collision name='collision'>
          <geometry>
            <cylinder>
              <radius>0.178172</radius>
              <length>0.041845</length>
            </cylinder>
          </geometry>
          <surface>
            <contact>
              <ode>
                <min_depth>0.003</min_depth>
              </ode>
            </contact>
            <bounce/>
            <friction>
              <torsional>
                <ode/>
              </torsional>
              <ode/>
            </friction>
          </surface>
          <max_contacts>10</max_contacts>
        </collision>
        <visual name='visual'>
          <pose frame=''>0 0 0 1.3021 -0 0</pose>
          <geometry>
            <mesh>
              <uri>model://prius_hybrid/meshes/Hybrid.obj</uri>
              <scale>0.01 0.01 0.01</scale>
              <submesh>
                <name>Steering_Wheel</name>
                <center>1</center>
              </submesh>
            </mesh>
          </geometry>
        </visual>
        <self_collide>0</self_collide>
        <kinematic>0</kinematic>
      </link>
      <link name='front_left_wheel'>
        <pose frame=''>0.76 -1.41 0.3 0 -0 0</pose>
        <inertial>
          <mass>11</mass>
          <inertia>
            <ixx>0.586312</ixx>
            <ixy>0</ixy>
            <iyy>0.335529</iyy>
            <ixz>0</ixz>
            <iyz>0</iyz>
            <izz>0.335529</izz>
          </inertia>
        </inertial>
        <visual name='visual'>
          <pose frame=''>0.04 0 0 0 -0 0</pose>
          <geometry>
            <mesh>
              <uri>model://prius_hybrid/meshes/Hybrid.obj</uri>
              <scale>0.01 0.01 0.01</scale>
              <submesh>
                <name>Wheel_Front_Left_</name>
                <center>1</center>
              </submesh>
            </mesh>
          </geometry>
        </visual>
        <collision name='collision'>
          <pose frame=''>0 0 0 3.14159 1.57079 3.14159</pose>
          <geometry>
            <sphere>
              <radius>0.31265</radius>
            </sphere>
          </geometry>
          <surface>
            <friction>
              <ode>
                <mu>0.9</mu>
                <mu2>0.9</mu2>
                <slip1>0</slip1>
                <slip2>0</slip2>
              </ode>
              <torsional>
                <ode/>
              </torsional>
            </friction>
            <contact>
              <ode>
                <min_depth>0.001</min_depth>
                <kp>1e+09</kp>
              </ode>
            </contact>
            <bounce/>
          </surface>
          <max_contacts>10</max_contacts>
        </collision>
        <self_collide>0</self_collide>
        <kinematic>0</kinematic>
      </link>
      <link name='front_right_wheel'>
        <pose frame=''>-0.76 -1.41 0.3 0 -0 0</pose>
        <inertial>
          <mass>11</mass>
          <inertia>
            <ixx>0.586312</ixx>
            <ixy>0</ixy>
            <iyy>0.335529</iyy>
            <ixz>0</ixz>
            <iyz>0</iyz>
            <izz>0.335529</izz>
          </inertia>
        </inertial>
        <visual name='visual'>
          <pose frame=''>-0.04 0 0 0 -0 0</pose>
          <pose frame=''>0 0 0 0 -0 0</pose>
          <geometry>
            <mesh>
              <uri>model://prius_hybrid/meshes/Hybrid.obj</uri>
              <scale>0.01 0.01 0.01</scale>
              <submesh>
                <name>Wheel_Front_Right</name>
                <center>1</center>
              </submesh>
            </mesh>
          </geometry>
        </visual>
        <collision name='collision'>
          <pose frame=''>0 0 0 3.14159 1.57079 3.14159</pose>
          <geometry>
            <sphere>
              <radius>0.31265</radius>
            </sphere>
          </geometry>
          <surface>
            <friction>
              <ode>
                <mu>0.9</mu>
                <mu2>0.9</mu2>
                <slip1>0</slip1>
                <slip2>0</slip2>
              </ode>
              <torsional>
                <ode/>
              </torsional>
            </friction>
            <contact>
              <ode>
                <min_depth>0.001</min_depth>
                <kp>1e+09</kp>
              </ode>
            </contact>
            <bounce/>
          </surface>
          <max_contacts>10</max_contacts>
        </collision>
        <self_collide>0</self_collide>
        <kinematic>0</kinematic>
      </link>
      <link name='rear_left_wheel'>
        <pose frame=''>0.786 1.45 0.3 0 -0 0</pose>
        <inertial>
          <mass>11</mass>
          <inertia>
            <ixx>0.586312</ixx>
            <ixy>0</ixy>
            <iyy>0.335529</iyy>
            <ixz>0</ixz>
            <iyz>0</iyz>
            <izz>0.335529</izz>
          </inertia>
        </inertial>
        <visual name='visual'>
          <pose frame=''>0.04 0 0 0 -0 0</pose>
          <geometry>
            <mesh>
              <uri>model://prius_hybrid/meshes/Hybrid.obj</uri>
              <scale>0.01 0.01 0.01</scale>
              <submesh>
                <name>Wheel_Front_Left_</name>
                <center>1</center>
              </submesh>
            </mesh>
          </geometry>
        </visual>
        <collision name='collision'>
          <pose frame=''>0 0 0 3.14159 1.57079 3.14159</pose>
          <geometry>
            <sphere>
              <radius>0.31265</radius>
            </sphere>
          </geometry>
          <surface>
            <friction>
              <ode>
                <mu>1.1</mu>
                <mu2>1.1</mu2>
                <slip1>0</slip1>
                <slip2>0</slip2>
              </ode>
              <torsional>
                <ode/>
              </torsional>
            </friction>
            <contact>
              <ode>
                <min_depth>0.001</min_depth>
                <kp>1e+09</kp>
              </ode>
            </contact>
            <bounce/>
          </surface>
          <max_contacts>10</max_contacts>
        </collision>
        <self_collide>0</self_collide>
        <kinematic>0</kinematic>
      </link>
      <link name='rear_right_wheel'>
        <pose frame=''>-0.786 1.45 0.3 0 -0 0</pose>
        <inertial>
          <mass>11</mass>
          <inertia>
            <ixx>0.586312</ixx>
            <ixy>0</ixy>
            <iyy>0.335529</iyy>
            <ixz>0</ixz>
            <iyz>0</iyz>
            <izz>0.335529</izz>
          </inertia>
        </inertial>
        <visual name='visual'>
          <pose frame=''>-0.04 0 0 0 -0 0</pose>
          <geometry>
            <mesh>
              <uri>model://prius_hybrid/meshes/Hybrid.obj</uri>
              <scale>0.01 0.01 0.01</scale>
              <submesh>
                <name>Wheel_Front_Right</name>
                <center>1</center>
              </submesh>
            </mesh>
          </geometry>
        </visual>
        <collision name='collision'>
          <pose frame=''>0 0 0 3.14159 1.57079 3.14159</pose>
          <geometry>
            <sphere>
              <radius>0.31265</radius>
            </sphere>
          </geometry>
          <surface>
            <friction>
              <ode>
                <mu>1.1</mu>
                <mu2>1.1</mu2>
                <slip1>0</slip1>
                <slip2>0</slip2>
              </ode>
              <torsional>
                <ode/>
              </torsional>
            </friction>
            <contact>
              <ode>
                <min_depth>0.001</min_depth>
                <kp>1e+09</kp>
              </ode>
            </contact>
            <bounce/>
          </surface>
          <max_contacts>10</max_contacts>
        </collision>
        <self_collide>0</self_collide>
        <kinematic>0</kinematic>
      </link>
      <joint name='front_left_combined_joint' type='universal'>
        <pose frame=''>0 0 0 -0.087266 0 0</pose>
        <child>front_left_wheel</child>
        <parent>chassis</parent>
        <axis>
          <xyz>0 0 1</xyz>
          <limit>
            <lower>-0.8727</lower>
            <upper>0.8727</upper>
          </limit>
          <use_parent_model_frame>0</use_parent_model_frame>
          <dynamics>
            <spring_reference>0</spring_reference>
            <spring_stiffness>0</spring_stiffness>
          </dynamics>
        </axis>
        <axis2>
          <xyz>1 0 0</xyz>
          <dynamics>
            <friction>18.0474</friction>
            <spring_reference>0</spring_reference>
            <spring_stiffness>0</spring_stiffness>
          </dynamics>
          <use_parent_model_frame>0</use_parent_model_frame>
        </axis2>
      </joint>
      <joint name='front_right_combined_joint' type='universal'>
        <pose frame=''>0 0 0 -0.087266 0 0</pose>
        <child>front_right_wheel</child>
        <parent>chassis</parent>
        <axis>
          <xyz>0 0 1</xyz>
          <limit>
            <lower>-0.8727</lower>
            <upper>0.8727</upper>
          </limit>
          <use_parent_model_frame>0</use_parent_model_frame>
          <dynamics>
            <spring_reference>0</spring_reference>
            <spring_stiffness>0</spring_stiffness>
          </dynamics>
        </axis>
        <axis2>
          <xyz>1 0 0</xyz>
          <dynamics>
            <friction>18.0474</friction>
            <spring_reference>0</spring_reference>
            <spring_stiffness>0</spring_stiffness>
          </dynamics>
          <use_parent_model_frame>0</use_parent_model_frame>
        </axis2>
      </joint>
      <link name='rear_axle'>
        <pose frame=''>0 1.45 0.3 0 -0 0</pose>
        <inertial>
          <mass>30</mass>
          <inertia>
            <ixx>0.084375</ixx>
            <ixy>0</ixy>
            <iyy>4.64581</iyy>
            <ixz>0</ixz>
            <iyz>0</iyz>
            <izz>4.64581</izz>
          </inertia>
        </inertial>
        <visual name='visual'>
          <pose frame=''>0 0 0 3.14159 1.57079 3.14159</pose>
          <geometry>
            <cylinder>
              <length>1.357</length>
              <radius>0.075</radius>
            </cylinder>
          </geometry>
          <material>
            <script>
              <name>Gazebo/Grey</name>
              <uri>file://media/materials/scripts/gazebo.material</uri>
            </script>
          </material>
        </visual>
        <self_collide>0</self_collide>
        <kinematic>0</kinematic>
      </link>
      <joint name='rear_axle_joint' type='revolute'>
        <child>rear_axle</child>
        <parent>chassis</parent>
        <axis>
          <xyz>0 1 0</xyz>
          <limit>
            <lower>-0.0508906</lower>
            <upper>0.0508906</upper>
          </limit>
          <dynamics>
            <spring_stiffness>20000</spring_stiffness>
            <damping>2000</damping>
            <spring_reference>0</spring_reference>
          </dynamics>
          <use_parent_model_frame>0</use_parent_model_frame>
        </axis>
      </joint>
      <joint name='rear_left_wheel_joint' type='revolute'>
        <child>rear_left_wheel</child>
        <parent>rear_axle</parent>
        <axis>
          <xyz>1 0 0</xyz>
          <dynamics>
            <friction>12.0316</friction>
            <spring_reference>0</spring_reference>
            <spring_stiffness>0</spring_stiffness>
          </dynamics>
          <use_parent_model_frame>0</use_parent_model_frame>
          <limit>
            <lower>-1e+16</lower>
            <upper>1e+16</upper>
          </limit>
        </axis>
      </joint>
      <joint name='rear_right_wheel_joint' type='revolute'>
        <child>rear_right_wheel</child>
        <parent>rear_axle</parent>
        <axis>
          <xyz>1 0 0</xyz>
          <dynamics>
            <friction>12.0316</friction>
            <spring_reference>0</spring_reference>
            <spring_stiffness>0</spring_stiffness>
          </dynamics>
          <use_parent_model_frame>0</use_parent_model_frame>
          <limit>
            <lower>-1e+16</lower>
            <upper>1e+16</upper>
          </limit>
        </axis>
      </joint>
      <joint name='steering_joint' type='revolute'>
        <pose frame=''>-0.002 0 0 0 -0 0</pose>
        <parent>chassis</parent>
        <child>steering_wheel</child>
        <axis>
          <xyz>0 0.964095 0.265556</xyz>
          <limit>
            <lower>-7.85</lower>
            <upper>7.85</upper>
          </limit>
          <dynamics>
            <damping>1</damping>
            <spring_reference>0</spring_reference>
            <spring_stiffness>0</spring_stiffness>
          </dynamics>
          <use_parent_model_frame>1</use_parent_model_frame>
        </axis>
        <physics>
          <ode>
            <cfm_damping>1</cfm_damping>
            <limit>
              <cfm>0</cfm>
              <erp>0.2</erp>
            </limit>
          </ode>
        </physics>
      </joint>
    </model>
    <model name='water_tower'>
      <static>1</static>
      <link name='link'>
        <collision name='collision'>
          <geometry>
            <mesh>
              <uri>model://water_tower/meshes/water_tower.dae</uri>
            </mesh>
          </geometry>
          <max_contacts>10</max_contacts>
          <surface>
            <contact>
              <ode/>
            </contact>
            <bounce/>
            <friction>
              <torsional>
                <ode/>
              </torsional>
              <ode/>
            </friction>
          </surface>
        </collision>
        <visual name='visual'>
          <geometry>
            <mesh>
              <uri>model://water_tower/meshes/water_tower.dae</uri>
            </mesh>
          </geometry>
        </visual>
        <self_collide>0</self_collide>
        <kinematic>0</kinematic>
      </link>
      <pose frame=''>62.4685 17.3686 0 0 -0 0</pose>
    </model>
    <model name='radio_tower'>
      <static>1</static>
      <link name='link'>
        <collision name='collision'>
          <geometry>
            <mesh>
              <uri>model://radio_tower/meshes/radio_tower.dae</uri>
            </mesh>
          </geometry>
          <max_contacts>10</max_contacts>
          <surface>
            <contact>
              <ode/>
            </contact>
            <bounce/>
            <friction>
              <torsional>
                <ode/>
              </torsional>
              <ode/>
            </friction>
          </surface>
        </collision>
        <visual name='visual'>
          <geometry>
            <mesh>
              <uri>model://radio_tower/meshes/radio_tower.dae</uri>
            </mesh>
          </geometry>
        </visual>
        <self_collide>0</self_collide>
        <kinematic>0</kinematic>
      </link>
      <pose frame=''>-152.748 80.1344 0 0 -0 0</pose>
    </model>
    <state world_name='default'>
      <sim_time>246 646000000</sim_time>
      <real_time>253 668413768</real_time>
      <wall_time>1511726708 548669008</wall_time>
      <iterations>246646</iterations>
      <model name='bus'>
        <pose frame=''>22.0685 -30.3747 0 0 -0 0</pose>
        <scale>1 1 1</scale>
        <link name='link'>
          <pose frame=''>22.0685 -30.3747 0 0 -0 0</pose>
          <velocity>0 0 0 0 -0 0</velocity>
          <acceleration>0 0 0 0 -0 0</acceleration>
          <wrench>0 0 0 0 -0 0</wrench>
        </link>
      </model>
      <model name='fire_truck'>
        <pose frame=''>48.4895 0.921966 0 0 -0 0</pose>
        <scale>1 1 1</scale>
        <link name='link'>
          <pose frame=''>48.4895 0.921966 0 0 -0 0</pose>
          <velocity>0 0 0 0 -0 0</velocity>
          <acceleration>0 0 0 0 -0 0</acceleration>
          <wrench>0 0 0 0 -0 0</wrench>
        </link>
      </model>
      <model name='ground_plane'>
        <pose frame=''>0 0 0 0 -0 0</pose>
        <scale>1 1 1</scale>
        <link name='link'>
          <pose frame=''>0 0 0 0 -0 0</pose>
          <velocity>0 0 0 0 -0 0</velocity>
          <acceleration>0 0 0 0 -0 0</acceleration>
          <wrench>0 0 0 0 -0 0</wrench>
        </link>
      </model>
      <model name='oak_tree_clone'>
        <pose frame=''>31.2842 5.74333 0 0 -0 0</pose>
        <scale>1 1 1</scale>
        <link name='link'>
          <pose frame=''>31.2842 5.74333 0 0 -0 0</pose>
          <velocity>0 0 0 0 -0 0</velocity>
          <acceleration>0 0 0 0 -0 0</acceleration>
          <wrench>0 0 0 0 -0 0</wrench>
        </link>
      </model>
      <model name='oak_tree_clone_0'>
        <pose frame=''>-8 17.5691 0 0 -0 0</pose>
        <scale>1 1 1</scale>
        <link name='link'>
          <pose frame=''>-8 17.5691 0 0 -0 0</pose>
          <velocity>0 0 0 0 -0 0</velocity>
          <acceleration>0 0 0 0 -0 0</acceleration>
          <wrench>0 0 0 0 -0 0</wrench>
        </link>
      </model>
      <model name='oak_tree_clone_1'>
        <pose frame=''>19.0726 14.9062 0 0 -0 0</pose>
        <scale>1 1 1</scale>
        <link name='link'>
          <pose frame=''>19.0726 14.9062 0 0 -0 0</pose>
          <velocity>0 0 0 0 -0 0</velocity>
          <acceleration>0 0 0 0 -0 0</acceleration>
          <wrench>0 0 0 0 -0 0</wrench>
        </link>
      </model>
      <model name='oak_tree_clone_2'>
        <pose frame=''>-22.3034 0.187197 0 0 -0 0</pose>
        <scale>1 1 1</scale>
        <link name='link'>
          <pose frame=''>-22.3034 0.187197 0 0 -0 0</pose>
          <velocity>0 0 0 0 -0 0</velocity>
          <acceleration>0 0 0 0 -0 0</acceleration>
          <wrench>0 0 0 0 -0 0</wrench>
        </link>
      </model>
      <model name='oak_tree_clone_3'>
        <pose frame=''>17.329 -7.63255 0 0 -0 0</pose>
        <scale>1 1 1</scale>
        <link name='link'>
          <pose frame=''>17.329 -7.63255 0 0 -0 0</pose>
          <velocity>0 0 0 0 -0 0</velocity>
          <acceleration>0 0 0 0 -0 0</acceleration>
          <wrench>0 0 0 0 -0 0</wrench>
        </link>
      </model>
      <model name='oak_tree_clone_4'>
        <pose frame=''>28.2562 -12.871 0 0 -0 0</pose>
        <scale>1 1 1</scale>
        <link name='link'>
          <pose frame=''>28.2562 -12.871 0 0 -0 0</pose>
          <velocity>0 0 0 0 -0 0</velocity>
          <acceleration>0 0 0 0 -0 0</acceleration>
          <wrench>0 0 0 0 -0 0</wrench>
        </link>
      </model>
      <model name='pine_tree'>
        <pose frame=''>-1.14655 -32.7072 0 0 -0 0</pose>
        <scale>1 1 1</scale>
        <link name='link'>
          <pose frame=''>-1.14655 -32.7072 0 0 -0 0</pose>
          <velocity>0 0 0 0 -0 0</velocity>
          <acceleration>0 0 0 0 -0 0</acceleration>
          <wrench>0 0 0 0 -0 0</wrench>
        </link>
      </model>
      <model name='pine_tree_0'>
        <pose frame=''>-21.297 -19.5762 0 0 -0 0</pose>
        <scale>1 1 1</scale>
        <link name='link'>
          <pose frame=''>-21.297 -19.5762 0 0 -0 0</pose>
          <velocity>0 0 0 0 -0 0</velocity>
          <acceleration>0 0 0 0 -0 0</acceleration>
          <wrench>0 0 0 0 -0 0</wrench>
        </link>
      </model>
      <model name='pine_tree_1'>
        <pose frame=''>2.23327 -4.24022 0 0 -0 0</pose>
        <scale>1 1 1</scale>
        <link name='link'>
          <pose frame=''>2.23327 -4.24022 0 0 -0 0</pose>
          <velocity>0 0 0 0 -0 0</velocity>
          <acceleration>0 0 0 0 -0 0</acceleration>
          <wrench>0 0 0 0 -0 0</wrench>
        </link>
      </model>
      <model name='prius_hybrid'>
        <pose frame=''>10.4616 1.93185 0.01164 -2e-06 0 0.000598</pose>
        <scale>1 1 1</scale>
        <link name='chassis'>
          <pose frame=''>10.4616 1.93185 0.01164 -2e-06 0 0.000598</pose>
          <velocity>1.4e-05 -2e-05 5e-06 -1e-06 -0 9e-06</velocity>
          <acceleration>0 -0 -0 0 -0 0</acceleration>
          <wrench>3e-06 -1.2e-05 -0 0 -0 0</wrench>
        </link>
        <link name='front_left_wheel'>
          <pose frame=''>11.2224 0.522307 0.31165 0.002833 0.005394 0.06229</pose>
          <velocity>2.7e-05 -1.3e-05 1.7e-05 4e-05 8.5e-05 0.000952</velocity>
          <acceleration>0 -0 -0 0 -0 0</acceleration>
          <wrench>0 -0 -0 0 -0 0</wrench>
        </link>
        <link name='front_right_wheel'>
          <pose frame=''>9.70241 0.521399 0.31165 0.005734 0.005306 0.061273</pose>
          <velocity>2.7e-05 -2.7e-05 1.7e-05 8.5e-05 8.5e-05 0.00092</velocity>
          <acceleration>0 -0 0 0 -0 -1e-06</acceleration>
          <wrench>0 -0 0 0 -0 0</wrench>
        </link>
        <link name='rear_axle'>
          <pose frame=''>10.4607 3.38185 0.311636 -2e-06 -6e-06 0.000598</pose>
          <velocity>0 -2e-05 3e-06 -1e-06 -4e-06 9e-06</velocity>
          <acceleration>0 -0 -0 -0.00092 -1e-06 0</acceleration>
          <wrench>0 -0 -0 0 -0 0</wrench>
        </link>
        <link name='rear_left_wheel'>
          <pose frame=''>11.2467 3.38232 0.31165 0.002616 -3e-06 0.000598</pose>
          <velocity>-0 -1.3e-05 1.3e-05 4e-05 0 9e-06</velocity>
          <acceleration>0 -0 -0 0 -0 0</acceleration>
          <wrench>0 -0 -0 0 -0 0</wrench>
        </link>
        <link name='rear_right_wheel'>
          <pose frame=''>9.6747 3.38138 0.31165 0.00562 1.2e-05 0.000598</pose>
          <velocity>1e-06 -2.7e-05 1.3e-05 8.6e-05 2e-06 9e-06</velocity>
          <acceleration>0 -0 -0 0 -0 0</acceleration>
          <wrench>0 -0 -0 0 -0 0</wrench>
        </link>
        <link name='steering_wheel'>
          <pose frame=''>10.8187 1.30465 0.998252 -1.09376 0.95419 0.399717</pose>
          <velocity>2e-06 -1.3e-05 -5e-06 -6e-06 0.009726 0.002688</velocity>
          <acceleration>0 -0 0 -9e-06 0.012657 0.00043</acceleration>
          <wrench>0 -0 0 0 -0 0</wrench>
        </link>
      </model>
      <model name='radio_tower'>
        <pose frame=''>-35.8877 16.7063 0 0 -0 0</pose>
        <scale>1 1 1</scale>
        <link name='link'>
          <pose frame=''>-35.8877 16.7063 0 0 -0 0</pose>
          <velocity>0 0 0 0 -0 0</velocity>
          <acceleration>0 0 0 0 -0 0</acceleration>
          <wrench>0 0 0 0 -0 0</wrench>
        </link>
      </model>
      <model name='suv'>
        <pose frame=''>-11.5275 -23.3683 0 0 -0 0</pose>
        <scale>1 1 1</scale>
        <link name='link'>
          <pose frame=''>-11.5275 -23.3683 0 0 -0 0</pose>
          <velocity>0 0 0 0 -0 0</velocity>
          <acceleration>0 0 0 0 -0 0</acceleration>
          <wrench>0 0 0 0 -0 0</wrench>
        </link>
      </model>
      <model name='suv_0'>
        <pose frame=''>-7.92143 10.0831 0 0 -0 0</pose>
        <scale>1 1 1</scale>
        <link name='link'>
          <pose frame=''>-7.92143 10.0831 0 0 -0 0</pose>
          <velocity>0 0 0 0 -0 0</velocity>
          <acceleration>0 0 0 0 -0 0</acceleration>
          <wrench>0 0 0 0 -0 0</wrench>
        </link>
      </model>
      <model name='tower_crane'>
        <pose frame=''>-39.4575 -32.1664 0 0 -0 0</pose>
        <scale>1 1 1</scale>
        <link name='link'>
          <pose frame=''>-39.4575 -32.1664 0 0 -0 0</pose>
          <velocity>0 0 0 0 -0 0</velocity>
          <acceleration>0 0 0 0 -0 0</acceleration>
          <wrench>0 0 0 0 -0 0</wrench>
        </link>
      </model>
      <model name='vrc_driving_terrain'>
        <pose frame=''>-1.87065 -3.0804 0 0 -0 0</pose>
        <scale>1 1 1</scale>
        <link name='grass_plane'>
          <pose frame=''>-1.87065 -3.0804 0 0 -0 0</pose>
          <velocity>0 0 0 0 -0 0</velocity>
          <acceleration>0 0 0 0 -0 0</acceleration>
          <wrench>0 0 0 0 -0 0</wrench>
        </link>
        <link name='link'>
          <pose frame=''>-1.87065 -3.0804 0 0 -0 0</pose>
          <velocity>0 0 0 0 -0 0</velocity>
          <acceleration>0 0 0 0 -0 0</acceleration>
          <wrench>0 0 0 0 -0 0</wrench>
        </link>
      </model>
      <model name='water_tower'>
        <pose frame=''>62.4685 17.3686 0 0 -0 0</pose>
        <scale>1 1 1</scale>
        <link name='link'>
          <pose frame=''>62.4685 17.3686 0 0 -0 0</pose>
          <velocity>0 0 0 0 -0 0</velocity>
          <acceleration>0 0 0 0 -0 0</acceleration>
          <wrench>0 0 0 0 -0 0</wrench>
        </link>
      </model>
      <light name='sun'>
        <pose frame=''>0 0 10 0 -0 0</pose>
      </light>
    </state>
    <gui fullscreen='0'>
      <camera name='user_camera'>
        <pose frame=''>179.367 118.192 165.646 -0.000219 0.489376 -2.73609</pose>
        <view_controller>orbit</view_controller>
        <projection_type>perspective</projection_type>
      </camera>
    </gui>
  </world>
</sdf>
